Workbook

Sheet Outreach List
A1: Company | B1: Category | C1: City | D1: State | E1: Website | F1: Phone / Email | G1: Notes | H1: Status | I1: Last Contacted
A2: Fête Nashville | B2: Wedding planner | C2: Nashville | D2: TN | E2: https://fetenashville.com | G2: Luxury wedding planning firm, 15+ yrs | H2: Not contacted
A3: Laurie D'Anne Events | B3: Wedding planner | C3: Nashville | D3: TN | E3: https://lauriedeanneevents.com | G3: Luxury weddings + corporate, 17+ yrs | H3: Not contacted
A4: AmosEvents | B4: Wedding planner | C4: Nashville | D4: TN | G4: Award-winning; weddings, corporate, galas | H4: Not contacted
A5: H Three Events | B5: Wedding planner | C5: Nashville | D5: TN | G5: Weddings, corporate, parties (Hugh Howser) | H5: Not contacted
A6: Magnolia Wedding Company | B6: Wedding planner | C6: Nashville | D6: TN | G6: Full-service wedding planning | H6: Not contacted
A7: Southern Bella Events | B7: Wedding planner | C7: Nashville | D7: TN | G7: Middle TN weddings (Franklin, Leiper's Fork) | H7: Not contacted
A8: Siena & Co. Events | B8: Wedding planner | C8: Nashville | D8: TN | G8: Middle TN weddings | H8: Not contacted
A9: Vision in White Events | B9: Wedding planner | C9: Nashville | D9: TN | G9: Wedding/event coordination team | H9: Not contacted
A10: Big Events, Inc. | B10: Event planner / DMC | C10: Nashville | D10: TN | E10: https://bigeventsinc.com | G10: Corporate event planning + DMC, 25+ yrs | H10: Not contacted
A11: AMP Event Group (Nashville) | B11: Event planner / DMC | C11: Nashville | D11: TN | E11: https://amp-events.com | G11: DMC + corporate event production | H11: Not contacted
A12: Music City Events | B12: Event planner / DMC | C12: Nashville | D12: TN | E12: https://musiccityevents.net | G12: Corporate conferences, retreats, incentives | H12: Not contacted
A13: Cohera | B13: Event planner / DMC | C13: Nashville | D13: TN | E13: https://meetcohera.com | G13: Destination event planning, corporate retreats | H13: Not contacted
A14: Well-Planned Events | B14: Event planner / DMC | C14: Nashville | D14: TN | E14: https://wellplannedevents.com | G14: Destination management, custom hospitality | H14: Not contacted
A15: Latitude Longitude DMC | B15: Event planner / DMC | C15: Nashville | D15: TN | E15: https://bycrave.com | G15: DMC; conventions, corporate, weddings | H15: Not contacted
A16: Destination Musick City | B16: Event planner / DMC | C16: Nashville | D16: TN | E16: https://destinationmusickcity.com | G16: Full-service DMC | H16: Not contacted
A17: The Nashville Booking Agency | B17: Entertainment agency | C17: Nashville | D17: TN | E17: https://nashvillebookingagency.com | G17: Books talent for corporate/private events | H17: Not contacted
A18: EastCoast Entertainment (Nashville) | B18: Entertainment agency | C18: Nashville | D18: TN | E18: https://bookece.com | G18: Large agency; weddings + corporate | H18: Not contacted
A19: Tsunami Entertainment | B19: Entertainment agency | C19: Nashville | D19: TN | E19: https://tsunamientertainment.com | G19: Weddings, holiday parties, corporate | H19: Not contacted
A20: Spangler Entertainment | B20: Entertainment agency | C20: Nashville | D20: TN | E20: https://spanglerentertainment.com | G20: Event production; books live entertainment | H20: Not contacted
A21: Premier | The Entertainment Company | B21: Entertainment agency | C21: Nashville | D21: TN | E21: https://requestpremier.com | G21: 30 yrs; weddings, corporate, private | H21: Not contacted
... A25: Lovely Event Co. | B25: Wedding planner | C25: Fort Worth | D25: TX | E25: https://lovelyeventco.com | G25: Dallas + Fort Worth weddings | H25: Not contacted
A26: Everything Bridal | B26: Wedding planner | C26: Fort Worth | D26: TX | G26: Multi-tier wedding planning | H26: Not contacted
A27: Treasured Heart Events | B27: Wedding planner | C27: Fort Worth | D27: TX | G27: Boutique wedding planning | H27: Not contacted
A28: Wineglass Events | B28: Wedding planner | C28: Fort Worth | D28: TX | G28: Weddings since 2000 | H28: Not contacted
A29: Morgan Taylor Events | B29: Wedding planner | C29: Fort Worth | D29: TX | G29: Wedding planning | H29: Not contacted
A30: Perstefani's Weddings & Events | B30: Wedding planner | C30: Fort Worth | D30: TX | G30: Weddings + celebrations | H30: Not contacted
A31: Sunshine and Moonlight Events | B31: Event planner / DMC | C31: Fort Worth | D31: TX | G31: Weddings, corporate meetings, nonprofits | H31: Not contacted
A32: CM Promotions | B32: Event planner / DMC | C32: Fort Worth | D32: TX | E32: https://cmpromotions.co | G32: DFW weddings + corporate packages | H32: Not contacted
A33: Total Events DFW | B33: Event planner / DMC | C33: Fort Worth | D33: TX | E33: https://totaleventsdfw.com | G33: 20+ yrs; corporate; books entertainment | H33: Not contacted
A34: Brilliant Events, Inc. | B34: Event planner / DMC | C34: Fort Worth | D34: TX | E34: https://brillianteventsinc.com | G34: Corporate parties across major TX cities | H34: Not contacted
A35: B3 Entertainment Productions | B35: Entertainment agency | C35: Fort Worth | D35: TX | E35: https://b3talent.com | G35: Performers for DFW corporate/private events | H35: Not contacted
A36: THEY improv (DFW) | B36: Entertainment agency | C36: Fort Worth | D36: TX | E36: https://theyimprov.com | G36: Comedy/game-show corporate entertainment | H36: Not contacted
A37: Interactive Entertainment Group (DFW) | B37: Entertainment agency | C37: Fort Worth | D37: TX | E37: https://interactiveparty.com | G37: Interactive corporate entertainment, full metroplex | H37: Not contacted
A38: Pearl Events Austin | B38: Wedding planner | C38: Austin | D38: TX | G38: Top-rated Austin wedding planning | H38: Not contacted
A39: Austin Weddings by Corinna | B39: Wedding planner | C39: Austin | D39: TX | G39: CWP-certified; corporate background | H39: Not contacted
A40: Malleret Designs | B40: Wedding planner | C40: Austin | D40: TX | G40: Luxury weddings; Austin + destination | H40: Not contacted
A41: Yellow Umbrella Events & Design | B41: Wedding planner | C41: Austin | D41: TX | G41: Weddings, corporate, parties | H41: Not contacted
A42: Toast Entertainment (Austin) | B42: Wedding planner | C42: Austin | D42: TX | E42: https://toastent.com | G42: Wedding coordination + DJ/entertainment | H42: Not contacted
A43: Plan On It | B43: Event planner / DMC | C43: Austin | D43: TX | E43: https://eventagency.planonitatx.com | G43: Corporate event planners + Austin DMC | H43: Not contacted
...

Sheet Summary
A1: Outreach targets by city
A3: City | B3: Wedding planners | C3: Event planners / DMCs | D3: Entertainment agencies | E3: Total
A4: Nashville | B4: =COUNTIFS('Outreach List'!$C:$C,$A4,'Outreach List'!$B:$B,"Wedding planner") -> 8 | C4: =COUNTIFS('Outreach List'!$C:$C,$A4,'Outreach List'!$B:$B,"Event planner / DMC") -> 7 | D4: =COUNTIFS('Outreach List'!$C:$C,$A4,'Outreach List'!$B:$B,"Entertainment agency") -> 5 | E4: =SUM(B4:D4) -> 20
A5: Fort Worth | B5: =COUNTIFS('Outreach List'!$C:$C,$A5,'Outreach List'!$B:$B,"Wedding planner") -> 9 | C5: =COUNTIFS('Outreach List'!$C:$C,$A5,'Outreach List'!$B:$B,"Event planner / DMC") -> 4 | D5: =COUNTIFS('Outreach List'!$C:$C,$A5,'Outreach List'!$B:$B,"Entertainment agency") -> 3 | E5: =SUM(B5:D5) -> 16
A6: Austin | B6: =COUNTIFS('Outreach List'!$C:$C,$A6,'Outreach List'!$B:$B,"Wedding planner") -> 5 | C6: =COUNTIFS('Outreach List'!$C:$C,$A6,'Outreach List'!$B:$B,"Event planner / DMC") -> 8 | D6: =COUNTIFS('Outreach List'!$C:$C,$A6,'Outreach List'!$B:$B,"Entertainment agency") -> 1 | E6: =SUM(B6:D6) -> 14
A7: Dallas | B7: =COUNTIFS('Outreach List'!$C:$C,$A7,'Outreach List'!$B:$B,"Wedding planner") -> 3 | C7: =COUNTIFS('Outreach List'!$C:$C,$A7,'Outreach List'!$B:$B,"Event planner / DMC") -> 8 | D7: =COUNTIFS('Outreach List'!$C:$C,$A7,'Outreach List'!$B:$B,"Entertainment agency") -> 4 | E7: =SUM(B7:D7) -> 15
A8: Houston | B8: =COUNTIFS('Outreach List'!$C:$C,$A8,'Outreach List'!$B:$B,"Wedding planner") -> 4 | C8: =COUNTIFS('Outreach List'!$C:$C,$A8,'Outreach List'!$B:$B,"Event planner / DMC") -> 4 | D8: =COUNTIFS('Outreach List'!$C:$C,$A8,'Outreach List'!$B:$B,"Entertainment agency") -> 7 | E8: =SUM(B8:D8) -> 15
A9: Denver | B9: =COUNTIFS('Outreach List'!$C:$C,$A9,'Outreach List'!$B:$B,"Wedding planner") -> 4 | C9: =COUNTIFS('Outreach List'!$C:$C,$A9,'Outreach List'!$B:$B,"Event planner / DMC") -> 4 | D9: =COUNTIFS('Outreach List'!$C:$C,$A9,'Outreach List'!$B:$B,"Entertainment agency") -> 6 | E9: =SUM(B9:D9) -> 14
A10: Phoenix | B10: =COUNTIFS('Outreach List'!$C:$C,$A10,'Outreach List'!$B:$B,"Wedding planner") -> 7 | C10: =COUNTIFS('Outreach List'!$C:$C,$A10,'Outreach List'!$B:$B,"Event planner / DMC") -> 4 | D10: =COUNTIFS('Outreach List'!$C:$C,$A10,'Outreach List'!$B:$B,"Entertainment agency") -> 3 | E10: =SUM(B10:D10) -> 14
A11: Atlanta | B11: =COUNTIFS('Outreach List'!$C:$C,$A11,'Outreach List'!$B:$B,"Wedding planner") -> 3 | C11: =COUNTIFS('Outreach List'!$C:$C,$A11,'Outreach List'!$B:$B,"Event planner / DMC") -> 6 | D11: =COUNTIFS('Outreach List'!$C:$C,$A11,'Outreach List'!$B:$B,"Entertainment agency") -> 8 | E11: =SUM(B11:D11) -> 17
A12: Charlotte | B12: =COUNTIFS('Outreach List'!$C:$C,$A12,'Outreach List'!$B:$B,"Wedding planner") -> 7 | C12: =COUNTIFS('Outreach List'!$C:$C,$A12,'Outreach List'!$B:$B,"Event planner / DMC") -> 7 | D12: =COUNTIFS('Outreach List'!$C:$C,$A12,'Outreach List'!$B:$B,"Entertainment agency") -> 4 | E12: =SUM(B12:D12) -> 18
A13: Las Vegas | B13: =COUNTIFS('Outreach List'!$C:$C,$A13,'Outreach List'!$B:$B,"Wedding planner") -> 3 | C13: =COUNTIFS('Outreach List'!$C:$C,$A13,'Outreach List'!$B:$B,"Event planner / DMC") -> 9 | D13: =COUNTIFS('Outreach List'!$C:$C,$A13,'Outreach List'!$B:$B,"Entertainment agency") -> 1 | E13: =SUM(B13:D13) -> 13
A14: Total | B14: =SUM(B4:B13) -> 53 | C14: =SUM(C4:C13) -> 61 | D14: =SUM(D4:D13) -> 42 | E14: =SUM(E4:E13) -> 156
A16: Note: companies verified via web research July 2026. Blank websites = confirm via a quick search of the company name + city.
